<?xml version="1.0"?>
<!-- created with Phobos 0.7 -->
<robot name="gripbot">

  <link name="arm_visual_link">
    <inertial>
      <origin xyz="0 0 0" rpy="0 0 0"/>
      <mass value="19.56717"/>
      <inertia ixx="0.503760" ixy="0" ixz="0" iyy="0.07578849" iyz="0" izz="0.50375514"/>
    </inertial>
    <visual name="arm_visual">
      <origin xyz="0 0 0" rpy="0 0 0"/>
      <geometry>
        <mesh filename="package://gripbot_description/meshes/stl/ID36.001.stl" scale="1.0 1.0 1.0"/>
      </geometry>
      <material name="Color_A05"/>
    </visual>
    <collision name="gripbot::arm_visual">
      <origin xyz="-0.00265 -0.19123 0.0002" rpy="0 0 0"/>
      <geometry>
        <box size="0.15244 0.53451 0.15245"/>
      </geometry>
    </collision>
    <collision name="gripbot::girdle_receptor_visual">
      <origin xyz="0 0 0" rpy="0 0 0"/>
      <geometry>
        <box size="0.18304 0.15204 0.15204"/>
      </geometry>
    </collision>
  </link>

  <link name="base_column_link">
    <inertial>
      <origin xyz="0 0 0" rpy="0 0 0"/>
      <mass value="33.204"/>
      <inertia ixx="0.17785" ixy="0" ixz="0" iyy="0.15673" iyz="0" izz="0.156739"/>
    </inertial>
    <visual name="base_column_receptor_visual">
      <origin xyz="0 -0.07833 0.30885" rpy="0 0 0"/>
      <geometry>
        <mesh filename="package://gripbot_description/meshes/stl/Circle.002.stl" scale="1.0 1.0 1.0"/>
      </geometry>
      <material name="Color_A05"/>
    </visual>
    <visual name="base_column_visual">
      <origin xyz="0 0 0" rpy="0 0 0"/>
      <geometry>
        <mesh filename="package://gripbot_description/meshes/stl/Circle.stl" scale="1.0 1.0 1.0"/>
      </geometry>
      <material name="Color_M07"/>
    </visual>
    <collision name="gripbot::base_column_mount_visual">
      <origin xyz="0 -0.07833 0.30885" rpy="0 0 0"/>
      <geometry>
        <box size="0.15655 0.17927 0.17927"/>
      </geometry>
    </collision>
    <collision name="gripbot::base_column_visual">
      <origin xyz="0 0 0.15275" rpy="0 0 0"/>
      <geometry>
        <box size="0.15423 0.15423 0.30549"/>
      </geometry>
    </collision>
  </link>

  <link name="base_mount_link">
    <inertial>
      <origin xyz="0 0 0" rpy="0 0 0"/>
      <mass value="240"/>
      <inertia ixx="2.4213" ixy="0" ixz="0" iyy="2.4213" iyz="0" izz="4.76351"/>
    </inertial>
    <visual name="base_mount_visual">
      <origin xyz="0 0 0" rpy="0 0 0"/>
      <geometry>
        <mesh filename="package://gripbot_description/meshes/stl/Circle.004.stl" scale="1.0 1.0 1.0"/>
      </geometry>
      <material name="Color_M07"/>
    </visual>
    <collision name="gripbot::base_mount_visual">
      <origin xyz="0 0 -0.01433" rpy="0 0 0"/>
      <geometry>
        <box size="0.4898 0.4898 0.0631"/>
      </geometry>
    </collision>
  </link>

  <link name="forearm_visual_link">
    <inertial>
      <origin xyz="0 0 0" rpy="0 0 0"/>
      <mass value="9.055067"/>
      <inertia ixx="0.067333" ixy="0" ixz="0" iyy="0.0673332" iyz="0" izz="0.028292"/>
    </inertial>
    <visual name="forearm_visual">
      <origin xyz="0 0 0" rpy="0 0 0"/>
      <geometry>
        <mesh filename="package://gripbot_description/meshes/stl/ID82.001.stl" scale="1.0 1.0 1.0"/>
      </geometry>
      <material name="Color_M07"/>
    </visual>
    <collision name="forearm_collision">
      <origin xyz="0 0 0" rpy="1.5708 0 0"/>
      <geometry>
        <cylinder radius="0.07905" length="0.26549"/>
      </geometry>
    </collision>
    <collision name="forearm_mount_collision">
      <origin xyz="0 0 0" rpy="1.5708 0 1.5708"/>
      <geometry>
        <cylinder radius="0.0665" length="0.17955"/>
      </geometry>
    </collision>
  </link>

  <link name="girdle_visual_link">
    <inertial>
      <origin xyz="0 0 0" rpy="0 0 0"/>
      <mass value="8.62636"/>
      <inertia ixx="0.085577" ixy="0" ixz="0" iyy="0.085577" iyz="0" izz="0.034199"/>
    </inertial>
    <visual name="girdle_mount_visual">
      <origin xyz="0 0 0" rpy="0 0 0"/>
      <geometry>
        <mesh filename="package://gripbot_description/meshes/stl/Circle.005.stl" scale="1.0 1.0 1.0"/>
      </geometry>
      <material name="Color_A05"/>
    </visual>
    <visual name="girdle_receptor_visual">
      <origin xyz="0 0 0" rpy="0 0 0"/>
      <geometry>
        <mesh filename="package://gripbot_description/meshes/stl/Circle.001.stl" scale="1.0 1.0 1.0"/>
      </geometry>
      <material name="Color_A05"/>
    </visual>
    <visual name="girdle_visual">
      <origin xyz="0 0 0" rpy="0 0 0"/>
      <geometry>
        <mesh filename="package://gripbot_description/meshes/stl/Circle.003.stl" scale="1.0 1.0 1.0"/>
      </geometry>
      <material name="Color_A05"/>
    </visual>
    <collision name="gripbot::girdle_visual">
      <origin xyz="0 0 0.19929" rpy="0 0 0"/>
      <geometry>
        <box size="0.15423 0.15423 0.30864"/>
      </geometry>
    </collision>
  </link>

  <joint name="arm_visual_link" type="revolute">
    <origin xyz="0 -0.06624 0.34976" rpy="0 0 0"/>
    <parent link="girdle_visual_link"/>
    <child link="arm_visual_link"/>
    <axis xyz="1.0 0 0"/>
    <limit lower="-1.5708" upper="0.59341" effort="135000.0" velocity="6000.28319"/>
  </joint>

  <joint name="base_column_link" type="revolute">
    <origin xyz="0 0 0" rpy="0 0 0"/>
    <parent link="base_mount_link"/>
    <child link="base_column_link"/>
    <axis xyz="0 0 1.0"/>
    <limit lower="-3.14159" upper="3.14159" effort="135000.0" velocity="6000.28319"/>
  </joint>

  <joint name="forearm_visual_link" type="revolute">
    <origin xyz="-0.00268 -0.39555 -0.0001" rpy="0 0 0"/>
    <parent link="arm_visual_link"/>
    <child link="forearm_visual_link"/>
    <axis xyz="1.0 0 0"/>
    <limit lower="-1.5708" upper="2.18166" effort="135000.0" velocity="6000.28319"/>
  </joint>

  <joint name="girdle_visual_link" type="revolute">
    <origin xyz="0 -0.07833 0.30885" rpy="0 0 0"/>
    <parent link="base_column_link"/>
    <child link="girdle_visual_link"/>
    <axis xyz="1.0 0 0"/>
    <limit lower="-0.5236" upper="1.95477" effort="135000.0" velocity="6000.28319"/>
  </joint>

  <!-- Transmission -->
  <transmission name="base_column_tran1">
    <type>transmission_interface/SimpleTransmission</type>
    <joint name="base_column_link">
      <hardwareInterface>hardware_interface/EffortJointInterface</hardwareInterface>
    </joint>
    <actuator name="base_column_motor1">
      <hardwareInterface>hardware_interface/EffortJointInterface</hardwareInterface>
      <mechanicalReduction>1</mechanicalReduction>
    </actuator>
  </transmission>


  <transmission name="girdle_tran1">
    <type>transmission_interface/SimpleTransmission</type>
    <joint name="girdle_visual_link">
      <hardwareInterface>hardware_interface/EffortJointInterface</hardwareInterface>
    </joint>
    <actuator name="girdle_motor1">
      <hardwareInterface>hardware_interface/EffortJointInterface</hardwareInterface>
      <mechanicalReduction>1</mechanicalReduction>
    </actuator>
  </transmission>

  <transmission name="forearm_tran1">
    <type>transmission_interface/SimpleTransmission</type>
    <joint name="forearm_visual_link">
      <hardwareInterface>hardware_interface/EffortJointInterface</hardwareInterface>
    </joint>
    <actuator name="forearm_motor1">
      <hardwareInterface>hardware_interface/EffortJointInterface</hardwareInterface>
      <mechanicalReduction>1</mechanicalReduction>
    </actuator>
  </transmission>

  <transmission name="arm_tran1">
    <type>transmission_interface/SimpleTransmission</type>
    <joint name="arm_visual_link">
      <hardwareInterface>hardware_interface/EffortJointInterface</hardwareInterface>
    </joint>
    <actuator name="arm_motor1">
      <hardwareInterface>hardware_interface/EffortJointInterface</hardwareInterface>
      <mechanicalReduction>1</mechanicalReduction>
    </actuator>
  </transmission>

  <material name="Color_A05">
    <color rgba="1.0 0 0 1.0"/>
  </material>

  <material name="Color_M07">
    <color rgba="0.22745 0.22745 0.22745 1.0"/>
  </material>

  <!-- ros_control plugin -->
  <gazebo>
    <plugin name="gazebo_ros_control" filename="libgazebo_ros_control.so">
      <robotNamespace>/gripbot</robotNamespace>
      <robotSimType>gazebo_ros_control/DefaultRobotHWSim</robotSimType>
    </plugin>
  </gazebo>



  <gazebo reference="base_mount_link">
    <selfCollide>true</selfCollide>
    <static>true</static>
    <turnGravityOff>false</turnGravityOff>
  </gazebo>


  <gazebo reference="arm_visual_link">
    <mu1 value="500.0"/>
    <kp value="10.0"/>
    <kd value="1.0"/>
    <turnGravityOff>false</turnGravityOff>
  </gazebo>
  <gazebo reference="base_column_link">
    <mu1 value="500.0"/>
    <kp value="10.0"/>
    <kd value="1.0"/>
    <turnGravityOff>false</turnGravityOff>
  </gazebo>
  <gazebo reference="base_mount_link">
    <mu1 value="500.0"/>
    <kp value="10.0"/>
    <kd value="1.0"/>
    <turnGravityOff>false</turnGravityOff>
  </gazebo>
  <gazebo reference="forearm_visual_link">
    <mu1 value="500.0"/>
    <kp value="10.0"/>
    <kd value="1.0"/>
    <turnGravityOff>false</turnGravityOff>
  </gazebo>
  <gazebo reference="girdle_visual_link">
    <mu1 value="500.0"/>
    <kp value="10.0"/>
    <kd value="1.0"/>
    <turnGravityOff>false</turnGravityOff>
  </gazebo>

</robot>
